<?xml version="1.0"?>
<robot xmlns:xacro="http://wiki.ros.org/xacro" name="$(arg robot_model)_robot">
  <!--
    This is a top-level xacro instantiating the Gazebo-specific version of the
    'ur_robot' macro (ie: 'ur_robot_gazebo') and passing it values for all its
    required arguments.

    This file should be considered the Gazebo-specific variant of the file
    with the same name in the ur_description package. It accepts the same
    arguments, but instead of configuring everything for a real robot, will
    generate a Gazebo-compatible URDF with a ros_control hardware_interface
    attached to it.

    Only use this top-level xacro if you plan on spawning the robot in Gazebo
    'by itself', without any gripper or any other geometry attached.

    If you need to attach an end-effector, camera or need to integrate the
    robot into a larger workcell and want to spawn that as a single entity in
    Gazebo, DO NOT EDIT THIS FILE.

    Instead: create a new top-level xacro, give it a proper name, include the
    required '.xacro' files, instantiate the models (ie: call the macros) and
    connect everything by adding the appropriate joints.
  -->

  <!--
    Import main macro.

    NOTE: this imports the Gazebo-wrapper main macro, NOT the regular
          xacro macro (which is hosted by ur_description).
  -->
  <xacro:include filename="$(find ur_gazebo)/urdf/ur_macro.xacro"/>

  <!--Declare arguments -->
  <xacro:arg name="joint_limit_params" default=""/>
  <xacro:arg name="physical_params" default=""/>
  <xacro:arg name="kinematics_params" default=""/>
  <xacro:arg name="visual_params" default=""/>
  <!--
    legal values:
      - hardware_interface/PositionJointInterface
      - hardware_interface/VelocityJointInterface
      - hardware_interface/EffortJointInterface

    NOTE: this value must correspond to the controller configured in the
          controller .yaml files in the 'config' directory.
  -->
  <xacro:arg name="transmission_hw_interface" default="hardware_interface/EffortJointInterface"/>
  <xacro:arg name="safety_limits" default="false"/>
  <xacro:arg name="safety_pos_margin" default="0.15"/>
  <xacro:arg name="safety_k_position" default="20"/>

  <!-- Instantiate the Gazebo robot and pass it all the required arguments. -->
  <xacro:ur_robot_gazebo
    prefix=""
    joint_limits_parameters_file="$(arg joint_limit_params)"
    kinematics_parameters_file="$(arg kinematics_params)"
    physical_parameters_file="$(arg physical_params)"
    visual_parameters_file="$(arg visual_params)"
    transmission_hw_interface="$(arg transmission_hw_interface)"
    safety_limits="$(arg safety_limits)"
    safety_pos_margin="$(arg safety_pos_margin)"
    safety_k_position="$(arg safety_k_position)"
  />

  <!--
    Attach the Gazebo model to Gazebo's world frame.

    Note: if you're looking to integrate a UR into a larger scene and need
    to add EEFs or other parts, DO NOT change this file or the 'world' link
    here. Create a NEW xacro instead and decide whether you need to add
    a 'world' link there.
  -->
  <link name="world"/>
  <link name="ur_stand">
    <visual>
      <origin xyz="0 0 0.35" rpy="0 0 0"/>
      <geometry>
        <box size="0.25 0.25 0.7"/>
      </geometry>
      <material name="blue">
        <color rgba="1 1 1 1"/>
      </material>
    </visual>
    <collision>
      <origin xyz="0 0 0.35" rpy="0 0 0"/>
        <geometry>
          <box size="0.25 0.25 0.7"/>
        </geometry>
    </collision>
    <inertial>
        <mass value="100.0" />
        <origin xyz="0 0 0" rpy="0 0 0" />
        <inertia ixx="0.03" iyy="0.03" izz="0.03" ixy="0.0" ixz="0.0" iyz="0.0" />
    </inertial>
  </link>
  <link name="table">
    <visual>
      <origin xyz="0 0 0" rpy="0 0 0"/>
      <geometry>
        <mesh filename="package://me5415_world/meshes/table.STL" scale="0.001 0.001 0.001"/>
      </geometry>
      <material name="table_color">
        <color rgba="0.5 0.5 0.5 1"/>
      </material>
    </visual>
    <collision>
      <origin xyz="0 0 0" rpy="0 0 0"/>
      <geometry>
        <mesh filename="package://me5415_world/meshes/table.STL" scale="0.001 0.001 0.001"/>
      </geometry>
    </collision>
    <inertial>
      <mass value="100.0" />
      <origin xyz="0 0 0" rpy="0 0 0" />
      <inertia ixx="0.03" iyy="0.03" izz="0.03" ixy="0.0" ixz="0.0" iyz="0.0" />
    </inertial>
  </link>

  <joint name="world_ur_stand_joint" type="fixed">
    <parent link="world"/>
    <child link="ur_stand"/>
    <origin xyz="0 0 -0.1" rpy="0 0 0"/>
  </joint>
  <joint name="ur_stand_ur_joint" type="fixed">
    <parent link="ur_stand"/>
    <child link="base_link"/>
    <origin xyz="0 0 0.701" rpy="0 0 0"/>
  </joint>
  <joint name="world_table_joint" type="fixed">
    <parent link="world"/>
    <child link="table"/>
    <origin xyz="0 0 0" rpy="0 0 0"/>
  </joint>
  <link name="gripper_base">
    <visual>
      <origin xyz="0 0 0" rpy="0 0 0"/>
      <geometry>
        <mesh filename="package://me5415_world/meshes/gripper_without_finger.STL" scale="0.001 0.001 0.001"/>
      </geometry>
      <material name="gripper_without_finger_color">
        <color rgba="0.5 0.5 0.5 1"/>
      </material>
    </visual>
    <collision>
      <origin xyz="0 0 0" rpy="0 0 0"/>
      <geometry>
        <mesh filename="package://me5415_world/meshes/gripper_without_finger.STL" scale="0.001 0.001 0.001"/>
      </geometry>
    </collision>
    <inertial>
      <mass value="0.1" />
      <origin xyz="0 0 0" rpy="0 0 0" />
      <inertia ixx="0.03" iyy="0.03" izz="0.03" ixy="0.0" ixz="0.0" iyz="0.0" />
    </inertial>
  </link>

  <link name="left_finger">
    <inertial>
      <mass value="0.05" />
      <inertia 
        ixx="0.005" ixy="0.0" ixz="0.0"
        iyy="0.005" iyz="0.0" izz="0.005" />
    </inertial>
    <visual>
      <geometry>
        <mesh filename="package://me5415_world/meshes/left_finger.STL" scale="0.001 0.001 0.001"/>
      </geometry>
    </visual>
    <collision>
      <geometry>
        <mesh filename="package://me5415_world/meshes/left_finger.STL" scale="0.001 0.001 0.001"/>
      </geometry>
    </collision>
  </link>

  <link name="right_finger">
    <inertial>
      <mass value="0.05" />
      <inertia 
        ixx="0.005" ixy="0.0" ixz="0.0"
        iyy="0.005" iyz="0.0" izz="0.005" />
    </inertial>
    <visual>
      <geometry>
        <mesh filename="package://me5415_world/meshes/right_finger.STL" scale="0.001 0.001 0.001"/>
      </geometry>
    </visual>
    <collision>
      <geometry>
        <mesh filename="package://me5415_world/meshes/right_finger.STL" scale="0.001 0.001 0.001"/>
      </geometry>
    </collision>
  </link>

  <joint name="tool0_gripper_base_joint" type="fixed">
    <parent link="tool0"/>
    <child link="gripper_base"/>
    <origin xyz="0 0 0" rpy="0 0 0"/>
  </joint>

  <joint name="left_finger_joint" type="prismatic">
    <parent link="gripper_base" />
    <child link="left_finger" />
    <origin xyz="0 0.007 0.187" rpy="0 0 0" />
    <axis xyz="0 1 0" />
    <limit lower="0" upper="0.075" effort="500" velocity="1.0" />
    <dynamics friction="1" damping="1" />
  </joint>

  <transmission name="left_finger_joint_tr">
    <type>transmission_interface/SimpleTransmission</type>
    <joint name="left_finger_joint">
        <hardwareInterface>hardware_interface/EffortJointInterface</hardwareInterface>
    </joint>
    <actuator name="left_finger_joint">
        <hardwareInterface>hardware_interface/EffortJointInterface</hardwareInterface>
      <mechanicalReduction>1</mechanicalReduction>
    </actuator>
  </transmission>

  <joint name="right_finger_joint" type="prismatic">
    <parent link="gripper_base" />
    <child link="right_finger" />
    <origin xyz="0 -0.007 0.187" rpy="0 0 0" />
    <axis xyz="0 -1 0" />
    <limit lower="0" upper="0.075" effort="500" velocity="1.0" />
    <mimic joint="left_finger_joint" />
    <dynamics friction="1" damping="1" />
  </joint>

  <transmission name="right_finger_joint_tr">
    <type>transmission_interface/SimpleTransmission</type>
    <joint name="right_finger_joint">
        <hardwareInterface>hardware_interface/EffortJointInterface</hardwareInterface>
    </joint>
    <actuator name="right_finger_joint">
        <hardwareInterface>hardware_interface/EffortJointInterface</hardwareInterface>
      <mechanicalReduction>1</mechanicalReduction>
    </actuator>
  </transmission>

  <!-- ros_control plugin -->
  <xacro:macro name="mimic_joint_plugin_gazebo" params="parent_joint mimic_joint has_pid:=false multiplier:=1.0 offset:=0 sensitiveness:=0.0 max_effort:=200.0 robot_namespace:=''">
    <gazebo>
        <plugin name="${mimic_joint}_mimic_joint_plugin" filename="libroboticsgroup_gazebo_mimic_joint_plugin.so">
            <joint>${parent_joint}</joint>
            <mimicJoint>${mimic_joint}</mimicJoint>
            <xacro:if value="${has_pid}">
            <hasPID />
            </xacro:if>
            <multiplier>${multiplier}</multiplier>
            <offset>${offset}</offset>
            <sensitiveness>${sensitiveness}</sensitiveness>
            <maxEffort>${max_effort}</maxEffort>
            <xacro:unless value="${robot_namespace == ''}">
                <robotNamespace>($robot_namespace)</robotNamespace>
            </xacro:unless>
        </plugin>
    </gazebo>
  </xacro:macro>

  <xacro:mimic_joint_plugin_gazebo parent_joint="left_finger_joint"
        mimic_joint="right_finger_joint" has_pid="false" multiplier="1.0"
        max_effort="200.0" />

  <gazebo>
    <plugin name="gazebo_grasp_fix" filename="libgazebo_grasp_fix.so">
        <arm>
            <arm_name>tool0</arm_name>
            <palm_link>wrist_3_link</palm_link>
            <gripper_link> left_finger </gripper_link>
            <gripper_link> right_finger </gripper_link>
        </arm>
        <forces_angle_tolerance>100</forces_angle_tolerance>
        <update_rate>10</update_rate>
        <grip_count_threshold>3</grip_count_threshold>
        <max_grip_count>10</max_grip_count>
        <release_tolerance>0.001</release_tolerance>
        <disable_collisions_on_attach>false</disable_collisions_on_attach>
        <contact_topic>__default_topic__</contact_topic>
    </plugin>
  </gazebo>

  <link name="soft_gripper"/>
  <joint name="soft_gripper_eef" type="fixed">
    <parent link="tool0"/>
    <child link="soft_gripper"/>
    <origin xyz="0 0 0.3" rpy="0 0 0"/>
  </joint>
</robot>
